Traceback (most recent call last):
  File "/opt/hostedtoolcache/Python/3.7.12/x64/lib/python3.7/site-packages/jupyter_cache/executors/utils.py", line 56, in single_nb_execution
    record_timing=False,
  File "/opt/hostedtoolcache/Python/3.7.12/x64/lib/python3.7/site-packages/nbclient/client.py", line 1093, in execute
    return NotebookClient(nb=nb, resources=resources, km=km, **kwargs).execute()
  File "/opt/hostedtoolcache/Python/3.7.12/x64/lib/python3.7/site-packages/nbclient/util.py", line 84, in wrapped
    return just_run(coro(*args, **kwargs))
  File "/opt/hostedtoolcache/Python/3.7.12/x64/lib/python3.7/site-packages/nbclient/util.py", line 62, in just_run
    return loop.run_until_complete(coro)
  File "/opt/hostedtoolcache/Python/3.7.12/x64/lib/python3.7/asyncio/base_events.py", line 587, in run_until_complete
    return future.result()
  File "/opt/hostedtoolcache/Python/3.7.12/x64/lib/python3.7/site-packages/nbclient/client.py", line 560, in async_execute
    cell, index, execution_count=self.code_cells_executed + 1
  File "/opt/hostedtoolcache/Python/3.7.12/x64/lib/python3.7/site-packages/nbclient/client.py", line 854, in async_execute_cell
    self._check_raise_for_error(cell, exec_reply)
  File "/opt/hostedtoolcache/Python/3.7.12/x64/lib/python3.7/site-packages/nbclient/client.py", line 756, in _check_raise_for_error
    raise CellExecutionError.from_cell_and_msg(cell, exec_reply_content)
nbclient.exceptions.CellExecutionError: An error occurred while executing the following cell:
------------------
# imports
import pickle
import powerlaw
import warnings
import pandas as pd
import networkx as nx
from fa2 import ForceAtlas2
from tqdm.notebook import tqdm
from collections import Counter

import matplotlib.pyplot as plt
from IPython.display import set_matplotlib_formats
from matplotlib import rc
plt.style.use('science')
set_matplotlib_formats('svg')
rc("text", usetex=False)

from pyvis.network import Network
from bokeh.io import output_notebook, show, save
from bokeh.models import Range1d, Circle, ColumnDataSource, MultiLine
from bokeh.plotting import figure
from bokeh.plotting import from_networkx

------------------

[0;31m---------------------------------------------------------------------------[0m
[0;31mModuleNotFoundError[0m                       Traceback (most recent call last)
[0;32m/tmp/ipykernel_3612/3801240647.py[0m in [0;36m<module>[0;34m[0m
[1;32m      5[0m [0;32mimport[0m [0mpandas[0m [0;32mas[0m [0mpd[0m[0;34m[0m[0;34m[0m[0m
[1;32m      6[0m [0;32mimport[0m [0mnetworkx[0m [0;32mas[0m [0mnx[0m[0;34m[0m[0;34m[0m[0m
[0;32m----> 7[0;31m [0;32mfrom[0m [0mfa2[0m [0;32mimport[0m [0mForceAtlas2[0m[0;34m[0m[0;34m[0m[0m
[0m[1;32m      8[0m [0;32mfrom[0m [0mtqdm[0m[0;34m.[0m[0mnotebook[0m [0;32mimport[0m [0mtqdm[0m[0;34m[0m[0;34m[0m[0m
[1;32m      9[0m [0;32mfrom[0m [0mcollections[0m [0;32mimport[0m [0mCounter[0m[0;34m[0m[0;34m[0m[0m

[0;31mModuleNotFoundError[0m: No module named 'fa2'
ModuleNotFoundError: No module named 'fa2'

