Traceback (most recent call last):
  File "/opt/hostedtoolcache/Python/3.7.12/x64/lib/python3.7/site-packages/jupyter_cache/executors/utils.py", line 56, in single_nb_execution
    record_timing=False,
  File "/opt/hostedtoolcache/Python/3.7.12/x64/lib/python3.7/site-packages/nbclient/client.py", line 1093, in execute
    return NotebookClient(nb=nb, resources=resources, km=km, **kwargs).execute()
  File "/opt/hostedtoolcache/Python/3.7.12/x64/lib/python3.7/site-packages/nbclient/util.py", line 84, in wrapped
    return just_run(coro(*args, **kwargs))
  File "/opt/hostedtoolcache/Python/3.7.12/x64/lib/python3.7/site-packages/nbclient/util.py", line 62, in just_run
    return loop.run_until_complete(coro)
  File "/opt/hostedtoolcache/Python/3.7.12/x64/lib/python3.7/asyncio/base_events.py", line 587, in run_until_complete
    return future.result()
  File "/opt/hostedtoolcache/Python/3.7.12/x64/lib/python3.7/site-packages/nbclient/client.py", line 560, in async_execute
    cell, index, execution_count=self.code_cells_executed + 1
  File "/opt/hostedtoolcache/Python/3.7.12/x64/lib/python3.7/site-packages/nbclient/client.py", line 854, in async_execute_cell
    self._check_raise_for_error(cell, exec_reply)
  File "/opt/hostedtoolcache/Python/3.7.12/x64/lib/python3.7/site-packages/nbclient/client.py", line 756, in _check_raise_for_error
    raise CellExecutionError.from_cell_and_msg(cell, exec_reply_content)
nbclient.exceptions.CellExecutionError: An error occurred while executing the following cell:
------------------
from nltk.tokenize import WordPunctTokenizer
from nltk.corpus import stopwords
from nltk.stem import WordNetLemmatizer
import time
from gensim.models.doc2vec import Doc2Vec
from collections import namedtuple
from node2vec import Node2Vec
import networkx as nx
import numpy as np
from sklearn.decomposition import PCA
import pandas as pd
#data = pd.read_csv('wiki_df.csv.gz')
#warnings.warn(msg)
------------------

[0;31m---------------------------------------------------------------------------[0m
[0;31mModuleNotFoundError[0m                       Traceback (most recent call last)
[0;32m/tmp/ipykernel_1659/2718015130.py[0m in [0;36m<module>[0;34m[0m
[1;32m      8[0m [0;32mimport[0m [0mnetworkx[0m [0;32mas[0m [0mnx[0m[0;34m[0m[0;34m[0m[0m
[1;32m      9[0m [0;32mimport[0m [0mnumpy[0m [0;32mas[0m [0mnp[0m[0;34m[0m[0;34m[0m[0m
[0;32m---> 10[0;31m [0;32mfrom[0m [0msklearn[0m[0;34m.[0m[0mdecomposition[0m [0;32mimport[0m [0mPCA[0m[0;34m[0m[0;34m[0m[0m
[0m[1;32m     11[0m [0;32mimport[0m [0mpandas[0m [0;32mas[0m [0mpd[0m[0;34m[0m[0;34m[0m[0m
[1;32m     12[0m [0;31m#data = pd.read_csv('wiki_df.csv.gz')[0m[0;34m[0m[0;34m[0m[0;34m[0m[0m

[0;31mModuleNotFoundError[0m: No module named 'sklearn'
ModuleNotFoundError: No module named 'sklearn'

