Traceback (most recent call last):
  File "/opt/hostedtoolcache/Python/3.7.12/x64/lib/python3.7/site-packages/jupyter_cache/executors/utils.py", line 56, in single_nb_execution
    record_timing=False,
  File "/opt/hostedtoolcache/Python/3.7.12/x64/lib/python3.7/site-packages/nbclient/client.py", line 1093, in execute
    return NotebookClient(nb=nb, resources=resources, km=km, **kwargs).execute()
  File "/opt/hostedtoolcache/Python/3.7.12/x64/lib/python3.7/site-packages/nbclient/util.py", line 84, in wrapped
    return just_run(coro(*args, **kwargs))
  File "/opt/hostedtoolcache/Python/3.7.12/x64/lib/python3.7/site-packages/nbclient/util.py", line 62, in just_run
    return loop.run_until_complete(coro)
  File "/opt/hostedtoolcache/Python/3.7.12/x64/lib/python3.7/asyncio/base_events.py", line 587, in run_until_complete
    return future.result()
  File "/opt/hostedtoolcache/Python/3.7.12/x64/lib/python3.7/site-packages/nbclient/client.py", line 560, in async_execute
    cell, index, execution_count=self.code_cells_executed + 1
  File "/opt/hostedtoolcache/Python/3.7.12/x64/lib/python3.7/site-packages/nbclient/client.py", line 854, in async_execute_cell
    self._check_raise_for_error(cell, exec_reply)
  File "/opt/hostedtoolcache/Python/3.7.12/x64/lib/python3.7/site-packages/nbclient/client.py", line 756, in _check_raise_for_error
    raise CellExecutionError.from_cell_and_msg(cell, exec_reply_content)
nbclient.exceptions.CellExecutionError: An error occurred while executing the following cell:
------------------
import re
import json
import string
import random 
import requests
import pickle
import warnings
import powerlaw
import numpy as np
import pandas as pd
from tqdm import tqdm
from typing import List
from itertools import chain
from bs4 import BeautifulSoup
from tqdm.notebook import tqdm
from dataclasses import dataclass

import networkx as nx
import littleballoffur

import nltk
from nltk.tokenize import WordPunctTokenizer
from nltk.corpus import stopwords
from nltk.stem import WordNetLemmatizer
------------------

[0;31m---------------------------------------------------------------------------[0m
[0;31mModuleNotFoundError[0m                       Traceback (most recent call last)
[0;32m/tmp/ipykernel_1660/4217365109.py[0m in [0;36m<module>[0;34m[0m
[1;32m     17[0m [0;34m[0m[0m
[1;32m     18[0m [0;32mimport[0m [0mnetworkx[0m [0;32mas[0m [0mnx[0m[0;34m[0m[0;34m[0m[0m
[0;32m---> 19[0;31m [0;32mimport[0m [0mlittleballoffur[0m[0;34m[0m[0;34m[0m[0m
[0m[1;32m     20[0m [0;34m[0m[0m
[1;32m     21[0m [0;32mimport[0m [0mnltk[0m[0;34m[0m[0;34m[0m[0m

[0;31mModuleNotFoundError[0m: No module named 'littleballoffur'
ModuleNotFoundError: No module named 'littleballoffur'

